<?xml version='1.0' encoding='utf-8'?>
<robot name="soarmoce_urdf">
  <link name="base">
    <inertial>
      <origin xyz="-0.0213710291112311 0.00673783911516032 -0.00351495988159654" rpy="0 0 0" />
      <mass value="0.184824839118779" />
      <inertia ixx="0.00014009159032767" ixy="5.14519314311599E-07" ixz="-2.19658664772978E-09" iyy="0.000150786507732308" iyz="-2.12017725499654E-05" izz="0.000176488838164293" />
    </inertial>
    <visual>
      <origin xyz="0 0 0" rpy="0 0 0" />
      <geometry>
        <mesh filename="/home/sunyuan/Code/Soarm_Moce/soarmMoce_sdk/src/soarmMoce_sdk/resources/meshes/base.STL" />
      </geometry>
      <material name="">
        <color rgba="0.964706 0.964706 0.952941 1.000000" />
      </material>
    </visual>
    <collision>
      <origin xyz="0 0 0" rpy="0 0 0" />
      <geometry>
        <mesh filename="/home/sunyuan/Code/Soarm_Moce/soarmMoce_sdk/src/soarmMoce_sdk/resources/meshes/base.STL" />
      </geometry>
    </collision>
  </link>
  <link name="shoulder">
    <inertial>
      <origin xyz="0.00431599372955423 -0.0391066695085737 0.0394888931376483" rpy="0 0 0" />
      <mass value="0.330894394655736" />
      <inertia ixx="0.000505546415051645" ixy="1.59518610653644E-06" ixz="-2.12499303650484E-05" iyy="0.000517530931668442" iyz="2.19651351970439E-05" izz="0.000127646885959192" />
    </inertial>
    <visual>
      <origin xyz="0 0 0" rpy="0 0 0" />
      <geometry>
        <mesh filename="/home/sunyuan/Code/Soarm_Moce/soarmMoce_sdk/src/soarmMoce_sdk/resources/meshes/shoulder.STL" />
      </geometry>
      <material name="">
        <color rgba="0.964706 0.964706 0.952941 1.000000" />
      </material>
    </visual>
    <collision>
      <origin xyz="0 0 0" rpy="0 0 0" />
      <geometry>
        <mesh filename="/home/sunyuan/Code/Soarm_Moce/soarmMoce_sdk/src/soarmMoce_sdk/resources/meshes/shoulder.STL" />
      </geometry>
    </collision>
  </link>
  <joint name="shoulder" type="revolute">
    <origin xyz="-0.021301 -0.019892 0.030313" rpy="0 0 0" />
    <parent link="base" />
    <child link="shoulder" />
    <axis xyz="0 0 -1" />
    <limit lower="-1.80000000" upper="1.80000000" effort="0" velocity="0" />
  </joint>
  <link name="shoulder_lift">
    <inertial>
      <origin xyz="-0.00324515070732309 0.0871957526382336 -0.0192601707678897" rpy="0 0 0" />
      <mass value="0.318710272679807" />
      <inertia ixx="0.000385454470204287" ixy="1.03441801394726E-05" ixz="-4.42203916060576E-06" iyy="0.000148614476916783" iyz="-4.60533290521661E-06" izz="0.000351054172172908" />
    </inertial>
    <visual>
      <origin xyz="0 0 0" rpy="0 0 0" />
      <geometry>
        <mesh filename="/home/sunyuan/Code/Soarm_Moce/soarmMoce_sdk/src/soarmMoce_sdk/resources/meshes/shoulder_lift.STL" />
      </geometry>
      <material name="">
        <color rgba="0.964706 0.964706 0.952941 1.000000" />
      </material>
    </visual>
    <collision>
      <origin xyz="0 0 0" rpy="0 0 0" />
      <geometry>
        <mesh filename="/home/sunyuan/Code/Soarm_Moce/soarmMoce_sdk/src/soarmMoce_sdk/resources/meshes/shoulder_lift.STL" />
      </geometry>
    </collision>
  </link>
  <joint name="shoulder_lift" type="revolute">
    <origin xyz="0.023908 -0.031327 0.098856" rpy="1.5708 0 1.5995" />
    <parent link="shoulder" />
    <child link="shoulder_lift" />
    <axis xyz="0 0 1" />
    <limit lower="-1.30000000" upper="1.30000000" effort="0" velocity="0" />
  </joint>
  <link name="elbow">
    <inertial>
      <origin xyz="-0.0832422888745699 0.0012113725012361 -0.0229169222713259" rpy="0 0 0" />
      <mass value="0.196597009085825" />
      <inertia ixx="7.92771752202201E-05" ixy="2.84545189052244E-06" ixz="-9.55291703398484E-07" iyy="0.000273362808050137" iyz="1.45502230872918E-08" izz="0.000221473559394089" />
    </inertial>
    <visual>
      <origin xyz="0 0 0" rpy="0 0 0" />
      <geometry>
        <mesh filename="/home/sunyuan/Code/Soarm_Moce/soarmMoce_sdk/src/soarmMoce_sdk/resources/meshes/elbow.STL" />
      </geometry>
      <material name="">
        <color rgba="0.964706 0.964706 0.952941 1.000000" />
      </material>
    </visual>
    <collision>
      <origin xyz="0 0 0" rpy="0 0 0" />
      <geometry>
        <mesh filename="/home/sunyuan/Code/Soarm_Moce/soarmMoce_sdk/src/soarmMoce_sdk/resources/meshes/elbow.STL" />
      </geometry>
    </collision>
  </link>
  <joint name="elbow" type="revolute">
    <origin xyz="-0.036111 0.12717 0.0005" rpy="0 0 0" />
    <parent link="shoulder_lift" />
    <child link="elbow" />
    <axis xyz="0 0 1" />
    <limit lower="-1.30000000" upper="1.30000000" effort="0" velocity="0" />
  </joint>
  <link name="wrist">
    <inertial>
      <origin xyz="-0.0353175824991667 9.81394374997002E-05 -0.0115136241068137" rpy="0 0 0" />
      <mass value="0.0706755636018164" />
      <inertia ixx="2.50939659898496E-05" ixy="8.58894507660815E-08" ixz="1.80285269647734E-06" iyy="3.5303799120401E-05" iyz="-1.3972021213463E-08" izz="1.99042479760721E-05" />
    </inertial>
    <visual>
      <origin xyz="0 0 0" rpy="0 0 0" />
      <geometry>
        <mesh filename="/home/sunyuan/Code/Soarm_Moce/soarmMoce_sdk/src/soarmMoce_sdk/resources/meshes/wrist.STL" />
      </geometry>
      <material name="">
        <color rgba="0.964706 0.964706 0.952941 1.000000" />
      </material>
    </visual>
    <collision>
      <origin xyz="0 0 0" rpy="0 0 0" />
      <geometry>
        <mesh filename="/home/sunyuan/Code/Soarm_Moce/soarmMoce_sdk/src/soarmMoce_sdk/resources/meshes/wrist.STL" />
      </geometry>
    </collision>
  </link>
  <joint name="wrist" type="revolute">
    <origin xyz="-0.15298 0.0021767 -0.003775" rpy="0 0 0" />
    <parent link="elbow" />
    <child link="wrist" />
    <axis xyz="0 0 1" />
    <limit lower="-1.30000000" upper="1.30000000" effort="0" velocity="0" />
  </joint>
  <link name="wrist_roll">
    <inertial>
      <origin xyz="-0.00534613057929257 0.000346192094794529 0.0265827947892246" rpy="0 0 0" />
      <mass value="0.0950264154360078" />
      <inertia ixx="4.26677683482621E-05" ixy="1.12540757127494E-06" ixz="6.80533672926815E-06" iyy="4.97447971463551E-05" iyz="-6.51926853197085E-07" izz="3.08661473876812E-05" />
    </inertial>
    <visual>
      <origin xyz="0 0 0" rpy="0 0 0" />
      <geometry>
        <mesh filename="/home/sunyuan/Code/Soarm_Moce/soarmMoce_sdk/src/soarmMoce_sdk/resources/meshes/wrist_roll.STL" />
      </geometry>
      <material name="">
        <color rgba="0.964706 0.964706 0.952941 1.000000" />
      </material>
    </visual>
    <collision>
      <origin xyz="0 0 0" rpy="0 0 0" />
      <geometry>
        <mesh filename="/home/sunyuan/Code/Soarm_Moce/soarmMoce_sdk/src/soarmMoce_sdk/resources/meshes/wrist_roll.STL" />
      </geometry>
    </collision>
  </link>
  <joint name="wrist_roll" type="revolute">
    <origin xyz="-0.061125 -0.00012939 -0.01895" rpy="0 -1.5708 0" />
    <parent link="wrist" />
    <child link="wrist_roll" />
    <axis xyz="0 0 -1" />
    <limit lower="-1.30000000" upper="1.30000000" effort="0" velocity="0" />
  </joint>
  <link name="gripper">
    <inertial>
      <origin xyz="0.0285152293814781 -0.0095219501591718 -0.0201256423347853" rpy="0 0 0" />
      <mass value="0.0206924066827897" />
      <inertia ixx="3.97506525437174E-06" ixy="2.37013710361177E-06" ixz="-1.80060833370411E-07" iyy="1.06886637310619E-05" iyz="5.98671833426615E-08" izz="9.11569538825076E-06" />
    </inertial>
    <visual>
      <origin xyz="0 0 0" rpy="0 0 0" />
      <geometry>
        <mesh filename="/home/sunyuan/Code/Soarm_Moce/soarmMoce_sdk/src/soarmMoce_sdk/resources/meshes/gripper.STL" />
      </geometry>
      <material name="">
        <color rgba="0.964706 0.964706 0.952941 1.000000" />
      </material>
    </visual>
    <collision>
      <origin xyz="0 0 0" rpy="0 0 0" />
      <geometry>
        <mesh filename="/home/sunyuan/Code/Soarm_Moce/soarmMoce_sdk/src/soarmMoce_sdk/resources/meshes/gripper.STL" />
      </geometry>
    </collision>
  </link>
  <joint name="gripper" type="revolute">
    <origin xyz="0.018466 -0.020147 0.023375" rpy="-1.5708 -1.5492 3.0625" />
    <parent link="wrist_roll" />
    <child link="gripper" />
    <axis xyz="0 0 -1" />
    <limit lower="-0.50000000" upper="1.30000000" effort="0" velocity="0" />
  </joint>
</robot>